[2024-05-31T16:38:51.309+0000] {processor.py:161} INFO - Started process (PID=54) to work on /home/airflow/.local/lib/python3.8/site-packages/airflow/example_dags/example_passing_params_via_test_command.py
[2024-05-31T16:38:51.313+0000] {processor.py:830} INFO - Processing file /home/airflow/.local/lib/python3.8/site-packages/airflow/example_dags/example_passing_params_via_test_command.py for tasks to queue
[2024-05-31T16:38:51.318+0000] {logging_mixin.py:188} INFO - [2024-05-31T16:38:51.316+0000] {dagbag.py:538} INFO - Filling up the DagBag from /home/airflow/.local/lib/python3.8/site-packages/airflow/example_dags/example_passing_params_via_test_command.py
[2024-05-31T16:38:51.352+0000] {processor.py:840} INFO - DAG(s) 'example_passing_params_via_test_command' retrieved from /home/airflow/.local/lib/python3.8/site-packages/airflow/example_dags/example_passing_params_via_test_command.py
[2024-05-31T16:39:22.629+0000] {processor.py:186} ERROR - Got an exception! Propagating...
Traceback (most recent call last):
  File "/home/airflow/.local/lib/python3.8/site-packages/sqlalchemy/engine/base.py", line 3371, in _wrap_pool_connect
    return fn()
  File "/home/airflow/.local/lib/python3.8/site-packages/sqlalchemy/pool/base.py", line 327, in connect
    return _ConnectionFairy._checkout(self)
  File "/home/airflow/.local/lib/python3.8/site-packages/sqlalchemy/pool/base.py", line 894, in _checkout
    fairy = _ConnectionRecord.checkout(pool)
  File "/home/airflow/.local/lib/python3.8/site-packages/sqlalchemy/pool/base.py", line 493, in checkout
    rec = pool._do_get()
  File "/home/airflow/.local/lib/python3.8/site-packages/sqlalchemy/pool/impl.py", line 146, in _do_get
    self._dec_overflow()
  File "/home/airflow/.local/lib/python3.8/site-packages/sqlalchemy/util/langhelpers.py", line 70, in __exit__
    compat.raise_(
  File "/home/airflow/.local/lib/python3.8/site-packages/sqlalchemy/util/compat.py", line 211, in raise_
    raise exception
  File "/home/airflow/.local/lib/python3.8/site-packages/sqlalchemy/pool/impl.py", line 143, in _do_get
    return self._create_connection()
  File "/home/airflow/.local/lib/python3.8/site-packages/sqlalchemy/pool/base.py", line 273, in _create_connection
    return _ConnectionRecord(self)
  File "/home/airflow/.local/lib/python3.8/site-packages/sqlalchemy/pool/base.py", line 388, in __init__
    self.__connect()
  File "/home/airflow/.local/lib/python3.8/site-packages/sqlalchemy/pool/base.py", line 691, in __connect
    pool.logger.debug("Error on connect(): %s", e)
  File "/home/airflow/.local/lib/python3.8/site-packages/sqlalchemy/util/langhelpers.py", line 70, in __exit__
    compat.raise_(
  File "/home/airflow/.local/lib/python3.8/site-packages/sqlalchemy/util/compat.py", line 211, in raise_
    raise exception
  File "/home/airflow/.local/lib/python3.8/site-packages/sqlalchemy/pool/base.py", line 686, in __connect
    self.dbapi_connection = connection = pool._invoke_creator(self)
  File "/home/airflow/.local/lib/python3.8/site-packages/sqlalchemy/engine/create.py", line 574, in connect
    return dialect.connect(*cargs, **cparams)
  File "/home/airflow/.local/lib/python3.8/site-packages/sqlalchemy/engine/default.py", line 598, in connect
    return self.dbapi.connect(*cargs, **cparams)
  File "/home/airflow/.local/lib/python3.8/site-packages/psycopg2/__init__.py", line 122, in connect
    conn = _connect(dsn, connection_factory=connection_factory, **kwasync)
psycopg2.OperationalError: could not translate host name "postgres" to address: Temporary failure in name resolution


The above exception was the direct cause of the following exception:

Traceback (most recent call last):
  File "/home/airflow/.local/lib/python3.8/site-packages/airflow/dag_processing/processor.py", line 182, in _run_file_processor
    _handle_dag_file_processing()
  File "/home/airflow/.local/lib/python3.8/site-packages/airflow/dag_processing/processor.py", line 163, in _handle_dag_file_processing
    result: tuple[int, int] = dag_file_processor.process_file(
  File "/home/airflow/.local/lib/python3.8/site-packages/airflow/utils/session.py", line 79, in wrapper
    return func(*args, session=session, **kwargs)
  File "/home/airflow/.local/lib/python3.8/site-packages/airflow/dag_processing/processor.py", line 859, in process_file
    serialize_errors = DagFileProcessor.save_dag_to_db(
  File "/home/airflow/.local/lib/python3.8/site-packages/airflow/api_internal/internal_api_call.py", line 114, in wrapper
    return func(*args, **kwargs)
  File "/home/airflow/.local/lib/python3.8/site-packages/airflow/utils/session.py", line 79, in wrapper
    return func(*args, session=session, **kwargs)
  File "/home/airflow/.local/lib/python3.8/site-packages/airflow/dag_processing/processor.py", line 895, in save_dag_to_db
    import_errors = DagBag._sync_to_db(dags=dags, processor_subdir=dag_directory, session=session)
  File "/home/airflow/.local/lib/python3.8/site-packages/airflow/utils/session.py", line 76, in wrapper
    return func(*args, **kwargs)
  File "/home/airflow/.local/lib/python3.8/site-packages/airflow/models/dagbag.py", line 657, in _sync_to_db
    for attempt in run_with_db_retries(logger=log):
  File "/home/airflow/.local/lib/python3.8/site-packages/tenacity/__init__.py", line 347, in __iter__
    do = self.iter(retry_state=retry_state)
  File "/home/airflow/.local/lib/python3.8/site-packages/tenacity/__init__.py", line 325, in iter
    raise retry_exc.reraise()
  File "/home/airflow/.local/lib/python3.8/site-packages/tenacity/__init__.py", line 158, in reraise
    raise self.last_attempt.result()
  File "/usr/local/lib/python3.8/concurrent/futures/_base.py", line 437, in result
    return self.__get_result()
  File "/usr/local/lib/python3.8/concurrent/futures/_base.py", line 389, in __get_result
    raise self._exception
  File "/home/airflow/.local/lib/python3.8/site-packages/airflow/models/dagbag.py", line 670, in _sync_to_db
    _serialize_dag_capturing_errors(dag, session, processor_subdir)
  File "/home/airflow/.local/lib/python3.8/site-packages/airflow/models/dagbag.py", line 635, in _serialize_dag_capturing_errors
    dag_was_updated = SerializedDagModel.write_dag(
  File "/home/airflow/.local/lib/python3.8/site-packages/airflow/utils/session.py", line 76, in wrapper
    return func(*args, **kwargs)
  File "/home/airflow/.local/lib/python3.8/site-packages/airflow/models/serialized_dag.py", line 157, in write_dag
    if session.scalar(
  File "/home/airflow/.local/lib/python3.8/site-packages/sqlalchemy/orm/session.py", line 1747, in scalar
    return self.execute(
  File "/home/airflow/.local/lib/python3.8/site-packages/sqlalchemy/orm/session.py", line 1716, in execute
    conn = self._connection_for_bind(bind)
  File "/home/airflow/.local/lib/python3.8/site-packages/sqlalchemy/orm/session.py", line 1555, in _connection_for_bind
    return self._transaction._connection_for_bind(
  File "/home/airflow/.local/lib/python3.8/site-packages/sqlalchemy/orm/session.py", line 750, in _connection_for_bind
    conn = bind.connect()
  File "/home/airflow/.local/lib/python3.8/site-packages/sqlalchemy/future/engine.py", line 412, in connect
    return super(Engine, self).connect()
  File "/home/airflow/.local/lib/python3.8/site-packages/sqlalchemy/engine/base.py", line 3325, in connect
    return self._connection_cls(self, close_with_result=close_with_result)
  File "/home/airflow/.local/lib/python3.8/site-packages/sqlalchemy/engine/base.py", line 96, in __init__
    else engine.raw_connection()
  File "/home/airflow/.local/lib/python3.8/site-packages/sqlalchemy/engine/base.py", line 3404, in raw_connection
    return self._wrap_pool_connect(self.pool.connect, _connection)
  File "/home/airflow/.local/lib/python3.8/site-packages/sqlalchemy/engine/base.py", line 3374, in _wrap_pool_connect
    Connection._handle_dbapi_exception_noconnection(
  File "/home/airflow/.local/lib/python3.8/site-packages/sqlalchemy/engine/base.py", line 2208, in _handle_dbapi_exception_noconnection
    util.raise_(
  File "/home/airflow/.local/lib/python3.8/site-packages/sqlalchemy/util/compat.py", line 211, in raise_
    raise exception
  File "/home/airflow/.local/lib/python3.8/site-packages/sqlalchemy/engine/base.py", line 3371, in _wrap_pool_connect
    return fn()
  File "/home/airflow/.local/lib/python3.8/site-packages/sqlalchemy/pool/base.py", line 327, in connect
    return _ConnectionFairy._checkout(self)
  File "/home/airflow/.local/lib/python3.8/site-packages/sqlalchemy/pool/base.py", line 894, in _checkout
    fairy = _ConnectionRecord.checkout(pool)
  File "/home/airflow/.local/lib/python3.8/site-packages/sqlalchemy/pool/base.py", line 493, in checkout
    rec = pool._do_get()
  File "/home/airflow/.local/lib/python3.8/site-packages/sqlalchemy/pool/impl.py", line 146, in _do_get
    self._dec_overflow()
  File "/home/airflow/.local/lib/python3.8/site-packages/sqlalchemy/util/langhelpers.py", line 70, in __exit__
    compat.raise_(
  File "/home/airflow/.local/lib/python3.8/site-packages/sqlalchemy/util/compat.py", line 211, in raise_
    raise exception
  File "/home/airflow/.local/lib/python3.8/site-packages/sqlalchemy/pool/impl.py", line 143, in _do_get
    return self._create_connection()
  File "/home/airflow/.local/lib/python3.8/site-packages/sqlalchemy/pool/base.py", line 273, in _create_connection
    return _ConnectionRecord(self)
  File "/home/airflow/.local/lib/python3.8/site-packages/sqlalchemy/pool/base.py", line 388, in __init__
    self.__connect()
  File "/home/airflow/.local/lib/python3.8/site-packages/sqlalchemy/pool/base.py", line 691, in __connect
    pool.logger.debug("Error on connect(): %s", e)
  File "/home/airflow/.local/lib/python3.8/site-packages/sqlalchemy/util/langhelpers.py", line 70, in __exit__
    compat.raise_(
  File "/home/airflow/.local/lib/python3.8/site-packages/sqlalchemy/util/compat.py", line 211, in raise_
    raise exception
  File "/home/airflow/.local/lib/python3.8/site-packages/sqlalchemy/pool/base.py", line 686, in __connect
    self.dbapi_connection = connection = pool._invoke_creator(self)
  File "/home/airflow/.local/lib/python3.8/site-packages/sqlalchemy/engine/create.py", line 574, in connect
    return dialect.connect(*cargs, **cparams)
  File "/home/airflow/.local/lib/python3.8/site-packages/sqlalchemy/engine/default.py", line 598, in connect
    return self.dbapi.connect(*cargs, **cparams)
  File "/home/airflow/.local/lib/python3.8/site-packages/psycopg2/__init__.py", line 122, in connect
    conn = _connect(dsn, connection_factory=connection_factory, **kwasync)
sqlalchemy.exc.OperationalError: (psycopg2.OperationalError) could not translate host name "postgres" to address: Temporary failure in name resolution

(Background on this error at: https://sqlalche.me/e/14/e3q8)
[2024-05-31T16:40:07.977+0000] {processor.py:161} INFO - Started process (PID=105) to work on /home/airflow/.local/lib/python3.8/site-packages/airflow/example_dags/example_passing_params_via_test_command.py
[2024-05-31T16:40:07.982+0000] {processor.py:830} INFO - Processing file /home/airflow/.local/lib/python3.8/site-packages/airflow/example_dags/example_passing_params_via_test_command.py for tasks to queue
[2024-05-31T16:40:07.989+0000] {logging_mixin.py:188} INFO - [2024-05-31T16:40:07.985+0000] {dagbag.py:538} INFO - Filling up the DagBag from /home/airflow/.local/lib/python3.8/site-packages/airflow/example_dags/example_passing_params_via_test_command.py
[2024-05-31T16:40:08.014+0000] {processor.py:840} INFO - DAG(s) 'example_passing_params_via_test_command' retrieved from /home/airflow/.local/lib/python3.8/site-packages/airflow/example_dags/example_passing_params_via_test_command.py
[2024-05-31T16:40:08.237+0000] {logging_mixin.py:188} INFO - [2024-05-31T16:40:08.236+0000] {dag.py:3036} INFO - Sync 1 DAGs
[2024-05-31T16:40:08.318+0000] {logging_mixin.py:188} INFO - [2024-05-31T16:40:08.318+0000] {dag.py:3823} INFO - Setting next_dagrun for example_passing_params_via_test_command to 2024-05-31 16:39:00+00:00, run_after=2024-05-31 16:40:00+00:00
[2024-05-31T16:40:08.464+0000] {processor.py:183} INFO - Processing /home/airflow/.local/lib/python3.8/site-packages/airflow/example_dags/example_passing_params_via_test_command.py took 0.498 seconds
[2024-05-31T16:40:38.769+0000] {processor.py:161} INFO - Started process (PID=157) to work on /home/airflow/.local/lib/python3.8/site-packages/airflow/example_dags/example_passing_params_via_test_command.py
[2024-05-31T16:40:38.770+0000] {processor.py:830} INFO - Processing file /home/airflow/.local/lib/python3.8/site-packages/airflow/example_dags/example_passing_params_via_test_command.py for tasks to queue
[2024-05-31T16:40:38.771+0000] {logging_mixin.py:188} INFO - [2024-05-31T16:40:38.771+0000] {dagbag.py:538} INFO - Filling up the DagBag from /home/airflow/.local/lib/python3.8/site-packages/airflow/example_dags/example_passing_params_via_test_command.py
[2024-05-31T16:40:38.781+0000] {processor.py:840} INFO - DAG(s) 'example_passing_params_via_test_command' retrieved from /home/airflow/.local/lib/python3.8/site-packages/airflow/example_dags/example_passing_params_via_test_command.py
[2024-05-31T16:40:38.794+0000] {logging_mixin.py:188} INFO - [2024-05-31T16:40:38.794+0000] {dag.py:3036} INFO - Sync 1 DAGs
[2024-05-31T16:40:38.831+0000] {logging_mixin.py:188} INFO - [2024-05-31T16:40:38.831+0000] {dag.py:3823} INFO - Setting next_dagrun for example_passing_params_via_test_command to 2024-05-31 16:39:00+00:00, run_after=2024-05-31 16:40:00+00:00
[2024-05-31T16:40:38.857+0000] {processor.py:183} INFO - Processing /home/airflow/.local/lib/python3.8/site-packages/airflow/example_dags/example_passing_params_via_test_command.py took 0.091 seconds
[2024-05-31T16:41:09.614+0000] {processor.py:161} INFO - Started process (PID=219) to work on /home/airflow/.local/lib/python3.8/site-packages/airflow/example_dags/example_passing_params_via_test_command.py
[2024-05-31T16:41:09.616+0000] {processor.py:830} INFO - Processing file /home/airflow/.local/lib/python3.8/site-packages/airflow/example_dags/example_passing_params_via_test_command.py for tasks to queue
[2024-05-31T16:41:09.618+0000] {logging_mixin.py:188} INFO - [2024-05-31T16:41:09.617+0000] {dagbag.py:538} INFO - Filling up the DagBag from /home/airflow/.local/lib/python3.8/site-packages/airflow/example_dags/example_passing_params_via_test_command.py
[2024-05-31T16:41:09.629+0000] {processor.py:840} INFO - DAG(s) 'example_passing_params_via_test_command' retrieved from /home/airflow/.local/lib/python3.8/site-packages/airflow/example_dags/example_passing_params_via_test_command.py
[2024-05-31T16:41:09.755+0000] {logging_mixin.py:188} INFO - [2024-05-31T16:41:09.755+0000] {dag.py:3036} INFO - Sync 1 DAGs
[2024-05-31T16:41:09.783+0000] {logging_mixin.py:188} INFO - [2024-05-31T16:41:09.783+0000] {dag.py:3823} INFO - Setting next_dagrun for example_passing_params_via_test_command to 2024-05-31 16:40:00+00:00, run_after=2024-05-31 16:41:00+00:00
[2024-05-31T16:41:09.809+0000] {processor.py:183} INFO - Processing /home/airflow/.local/lib/python3.8/site-packages/airflow/example_dags/example_passing_params_via_test_command.py took 0.198 seconds
[2024-05-31T16:41:40.781+0000] {processor.py:161} INFO - Started process (PID=275) to work on /home/airflow/.local/lib/python3.8/site-packages/airflow/example_dags/example_passing_params_via_test_command.py
[2024-05-31T16:41:40.783+0000] {processor.py:830} INFO - Processing file /home/airflow/.local/lib/python3.8/site-packages/airflow/example_dags/example_passing_params_via_test_command.py for tasks to queue
[2024-05-31T16:41:40.785+0000] {logging_mixin.py:188} INFO - [2024-05-31T16:41:40.784+0000] {dagbag.py:538} INFO - Filling up the DagBag from /home/airflow/.local/lib/python3.8/site-packages/airflow/example_dags/example_passing_params_via_test_command.py
[2024-05-31T16:41:40.797+0000] {processor.py:840} INFO - DAG(s) 'example_passing_params_via_test_command' retrieved from /home/airflow/.local/lib/python3.8/site-packages/airflow/example_dags/example_passing_params_via_test_command.py
[2024-05-31T16:41:40.820+0000] {logging_mixin.py:188} INFO - [2024-05-31T16:41:40.820+0000] {dag.py:3036} INFO - Sync 1 DAGs
[2024-05-31T16:41:40.847+0000] {logging_mixin.py:188} INFO - [2024-05-31T16:41:40.847+0000] {dag.py:3823} INFO - Setting next_dagrun for example_passing_params_via_test_command to 2024-05-31 16:40:00+00:00, run_after=2024-05-31 16:41:00+00:00
[2024-05-31T16:41:40.870+0000] {processor.py:183} INFO - Processing /home/airflow/.local/lib/python3.8/site-packages/airflow/example_dags/example_passing_params_via_test_command.py took 0.093 seconds
[2024-05-31T16:42:11.533+0000] {processor.py:161} INFO - Started process (PID=331) to work on /home/airflow/.local/lib/python3.8/site-packages/airflow/example_dags/example_passing_params_via_test_command.py
[2024-05-31T16:42:11.534+0000] {processor.py:830} INFO - Processing file /home/airflow/.local/lib/python3.8/site-packages/airflow/example_dags/example_passing_params_via_test_command.py for tasks to queue
[2024-05-31T16:42:11.535+0000] {logging_mixin.py:188} INFO - [2024-05-31T16:42:11.535+0000] {dagbag.py:538} INFO - Filling up the DagBag from /home/airflow/.local/lib/python3.8/site-packages/airflow/example_dags/example_passing_params_via_test_command.py
[2024-05-31T16:42:11.544+0000] {processor.py:840} INFO - DAG(s) 'example_passing_params_via_test_command' retrieved from /home/airflow/.local/lib/python3.8/site-packages/airflow/example_dags/example_passing_params_via_test_command.py
[2024-05-31T16:42:11.562+0000] {logging_mixin.py:188} INFO - [2024-05-31T16:42:11.562+0000] {dag.py:3036} INFO - Sync 1 DAGs
[2024-05-31T16:42:11.585+0000] {logging_mixin.py:188} INFO - [2024-05-31T16:42:11.585+0000] {dag.py:3823} INFO - Setting next_dagrun for example_passing_params_via_test_command to 2024-05-31 16:41:00+00:00, run_after=2024-05-31 16:42:00+00:00
[2024-05-31T16:42:11.603+0000] {processor.py:183} INFO - Processing /home/airflow/.local/lib/python3.8/site-packages/airflow/example_dags/example_passing_params_via_test_command.py took 0.072 seconds
